<sdf version="1.6">
    <!--  The following section here defines the physical properties of the model -->
    <model name="viper">
        <pose>0 0 0.053302 0 0 0</pose>
        <link name="X3/base_link">
            <pose frame="">0 0 0 0 -0 0</pose>
            <inertial>
                <pose frame="">0 0 0 0 -0 0</pose>
                <mass>1.5</mass>
                <inertia>
                    <ixx>0.0347563</ixx>
                    <ixy>0</ixy>
                    <ixz>0</ixz>
                    <iyy>0.07</iyy>
                    <iyz>0</iyz>
                    <izz>0.0977</izz>
                </inertia>
            </inertial>
            <collision name="X3/base_link_inertia_collision">
                <pose frame="">0 0 0 0 -0 0</pose>
                <geometry>
                    <box>
                        <size>0.47 0.47 0.11</size>
                    </box>
                </geometry>
            </collision>
            <visual name="X3/base_link_inertia_visual">
                <pose frame="">0 0 0 0 -0 0</pose>
                <geometry>
                    <mesh>
                        <scale>1 1 1</scale>
                        <!-- Pull in 3D model from Gazebo Fuel -->
                        <uri>https://fuel.ignitionrobotics.org/1.0/openrobotics/models/x3 uav/4/files/meshes/x3.dae</uri>
                    </mesh>
                </geometry>
            </visual>
            <!-- Add IMU sensor to main body -->
            <sensor name="imu_sensor" type="imu">
                <always_on>1</always_on>
                <update_rate>100</update_rate>
                <visualize>true</visualize>
                <topic>gazebo/imu</topic>
                <imu>
                <angular_velocity>
                    <x><noise type="gaussian"><mean>0</mean><stddev>0.001</stddev></noise></x>
                    <y><noise type="gaussian"><mean>0</mean><stddev>0.001</stddev></noise></y>
                    <z><noise type="gaussian"><mean>0</mean><stddev>0.001</stddev></noise></z>
                </angular_velocity>
                <linear_acceleration>
                    <x><noise type="gaussian"><mean>0</mean><stddev>0.001</stddev></noise></x>
                    <y><noise type="gaussian"><mean>0</mean><stddev>0.001</stddev></noise></y>
                    <z><noise type="gaussian"><mean>0</mean><stddev>0.001</stddev></noise></z>
                </linear_acceleration>
                </imu>
            </sensor>
        </link>
        <link name="X3/rotor_0">
            <pose frame="">0.13 -0.22 0.023 0 -0 0</pose>
            <inertial>
                <pose frame="">0 0 0 0 -0 0</pose>
                <mass>0.005</mass>
                <inertia>
                    <ixx>9.75e-07</ixx>
                    <ixy>0</ixy>
                    <ixz>0</ixz>
                    <iyy>4.17041e-05</iyy>
                    <iyz>0</iyz>
                    <izz>4.26041e-05</izz>
                </inertia>
            </inertial>
            <collision name="X3/rotor_0_collision">
                <pose frame="">0 0 0 0 -0 0</pose>
                <geometry>
                    <cylinder>
                        <length>0.005</length>
                        <radius>0.1</radius>
                    </cylinder>
                </geometry>
                <surface>
                    <contact>
                        <ode/>
                    </contact>
                    <friction>
                        <ode/>
                    </friction>
                </surface>
            </collision>
            <visual name="X3/rotor_0_visual">
                <pose frame="">0 0 0 0 -0 0</pose>
                <geometry>
                    <mesh>
                        <scale>0.1 0.1 0.1</scale>
                        <uri>https://fuel.ignitionrobotics.org/1.0/openrobotics/models/x3 uav/4/files/meshes/propeller_ccw.dae</uri>
                    </mesh>
                </geometry>
                <material>
                    <script>
                        <name>Gazebo/Blue</name>
                        <uri>file://media/materials/scripts/gazebo.material</uri>
                    </script>
                </material>
            </visual>
            <gravity>1</gravity>
            <velocity_decay/>
        </link>
        <joint name="X3/rotor_0_joint" type="revolute">
            <child>X3/rotor_0</child>
            <parent>X3/base_link</parent>
            <axis>
                <xyz>0 0 1</xyz>
                <limit>
                    <lower>-1e+16</lower>
                    <upper>1e+16</upper>
                </limit>
                <dynamics>
                    <spring_reference>0</spring_reference>
                    <spring_stiffness>0</spring_stiffness>
                </dynamics>
                <use_parent_model_frame>1</use_parent_model_frame>
            </axis>
        </joint>
        <link name="X3/rotor_1">
            <pose frame="">-0.13 0.2 0.023 0 -0 0</pose>
            <inertial>
                <pose frame="">0 0 0 0 -0 0</pose>
                <mass>0.005</mass>
                <inertia>
                    <ixx>9.75e-07</ixx>
                    <ixy>0</ixy>
                    <ixz>0</ixz>
                    <iyy>4.17041e-05</iyy>
                    <iyz>0</iyz>
                    <izz>4.26041e-05</izz>
                </inertia>
            </inertial>
            <collision name="X3/rotor_1_collision">
                <pose frame="">0 0 0 0 -0 0</pose>
                <geometry>
                    <cylinder>
                        <length>0.005</length>
                        <radius>0.1</radius>
                    </cylinder>
                </geometry>
                <surface>
                    <contact>
                        <ode/>
                    </contact>
                    <friction>
                        <ode/>
                    </friction>
                </surface>
            </collision>
            <visual name="X3/rotor_1_visual">
                <pose frame="">0 0 0 0 -0 0</pose>
                <geometry>
                    <mesh>
                        <scale>0.1 0.1 0.1</scale>
                        <uri>https://fuel.ignitionrobotics.org/1.0/openrobotics/models/x3 uav/4/files/meshes/propeller_ccw.dae</uri>
                    </mesh>
                </geometry>
                <material>
                    <script>
                        <name>Gazebo/Red</name>
                        <uri>file://media/materials/scripts/gazebo.material</uri>
                    </script>
                </material>
            </visual>
            <gravity>1</gravity>
            <velocity_decay/>
        </link>
        <joint name="X3/rotor_1_joint" type="revolute">
            <child>X3/rotor_1</child>
            <parent>X3/base_link</parent>
            <axis>
                <xyz>0 0 1</xyz>
                <limit>
                    <lower>-1e+16</lower>
                    <upper>1e+16</upper>
                </limit>
                <dynamics>
                    <spring_reference>0</spring_reference>
                    <spring_stiffness>0</spring_stiffness>
                </dynamics>
                <use_parent_model_frame>1</use_parent_model_frame>
            </axis>
        </joint>
        <link name="X3/rotor_2">
            <pose frame="">0.13 0.22 0.023 0 -0 0</pose>
            <inertial>
                <pose frame="">0 0 0 0 -0 0</pose>
                <mass>0.005</mass>
                <inertia>
                    <ixx>9.75e-07</ixx>
                    <ixy>0</ixy>
                    <ixz>0</ixz>
                    <iyy>4.17041e-05</iyy>
                    <iyz>0</iyz>
                    <izz>4.26041e-05</izz>
                </inertia>
            </inertial>
            <collision name="X3/rotor_2_collision">
                <pose frame="">0 0 0 0 -0 0</pose>
                <geometry>
                    <cylinder>
                        <length>0.005</length>
                        <radius>0.1</radius>
                    </cylinder>
                </geometry>
                <surface>
                    <contact>
                        <ode/>
                    </contact>
                    <friction>
                        <ode/>
                    </friction>
                </surface>
            </collision>
            <visual name="X3/rotor_2_visual">
                <pose frame="">0 0 0 0 -0 0</pose>
                <geometry>
                    <mesh>
                        <scale>0.1 0.1 0.1</scale>
                        <uri>https://fuel.ignitionrobotics.org/1.0/openrobotics/models/x3 uav/4/files/meshes/propeller_cw.dae</uri>
                    </mesh>
                </geometry>
                <material>
                    <script>
                        <name>Gazebo/Blue</name>
                        <uri>file://media/materials/scripts/gazebo.material</uri>
                    </script>
                </material>
            </visual>
            <gravity>1</gravity>
            <velocity_decay/>
        </link>
        <joint name="X3/rotor_2_joint" type="revolute">
            <child>X3/rotor_2</child>
            <parent>X3/base_link</parent>
            <axis>
                <xyz>0 0 1</xyz>
                <limit>
                    <lower>-1e+16</lower>
                    <upper>1e+16</upper>
                </limit>
                <dynamics>
                    <spring_reference>0</spring_reference>
                    <spring_stiffness>0</spring_stiffness>
                </dynamics>
                <use_parent_model_frame>1</use_parent_model_frame>
            </axis>
        </joint>
        <link name="X3/rotor_3">
            <pose frame="">-0.13 -0.2 0.023 0 -0 0</pose>
            <inertial>
                <pose frame="">0 0 0 0 -0 0</pose>
                <mass>0.005</mass>
                <inertia>
                    <ixx>9.75e-07</ixx>
                    <ixy>0</ixy>
                    <ixz>0</ixz>
                    <iyy>4.17041e-05</iyy>
                    <iyz>0</iyz>
                    <izz>4.26041e-05</izz>
                </inertia>
            </inertial>
            <collision name="X3/rotor_3_collision">
                <pose frame="">0 0 0 0 -0 0</pose>
                <geometry>
                    <cylinder>
                        <length>0.005</length>
                        <radius>0.1</radius>
                    </cylinder>
                </geometry>
                <surface>
                    <contact>
                        <ode/>
                    </contact>
                    <friction>
                        <ode/>
                    </friction>
                </surface>
            </collision>
            <visual name="X3/rotor_3_visual">
                <pose frame="">0 0 0 0 -0 0</pose>
                <geometry>
                    <mesh>
                        <scale>0.1 0.1 0.1</scale>
                        <uri>https://fuel.ignitionrobotics.org/1.0/openrobotics/models/x3 uav/4/files/meshes/propeller_cw.dae</uri>
                    </mesh>
                </geometry>
                <material>
                    <script>
                        <name>Gazebo/Red</name>
                        <uri>file://media/materials/scripts/gazebo.material</uri>
                    </script>
                </material>
            </visual>
            <gravity>1</gravity>
            <velocity_decay/>
        </link>
        <joint name="X3/rotor_3_joint" type="revolute">
            <child>X3/rotor_3</child>
            <parent>X3/base_link</parent>
            <axis>
                <xyz>0 0 1</xyz>
                <limit>
                    <lower>-1e+16</lower>
                    <upper>1e+16</upper>
                </limit>
                <dynamics>
                    <spring_reference>0</spring_reference>
                    <spring_stiffness>0</spring_stiffness>
                </dynamics>
                <use_parent_model_frame>1</use_parent_model_frame>
            </axis>
        </joint>

        <!-- Motors - initialise the motors with parameters -->
        <plugin
          filename="ignition-gazebo-multicopter-motor-model-system"
          name="gz::sim::systems::MulticopterMotorModel">
          <robotNamespace>X3</robotNamespace>
          <jointName>X3/rotor_0_joint</jointName>
          <linkName>X3/rotor_0</linkName>
          <turningDirection>ccw</turningDirection>
          <timeConstantUp>0.0125</timeConstantUp>
          <timeConstantDown>0.025</timeConstantDown>
          <maxRotVelocity>800.0</maxRotVelocity>
          <motorConstant>8.54858e-06</motorConstant>
          <momentConstant>0.016</momentConstant>
          <commandSubTopic>gazebo/command/motor_speed</commandSubTopic>
          <!-- Motor number switched to match 0 to 3 ccw starting from rear left -->
          <motorNumber>2</motorNumber>
          <rotorDragCoefficient>8.06428e-05</rotorDragCoefficient>
          <rollingMomentCoefficient>1e-06</rollingMomentCoefficient>
          <motorSpeedPubTopic>motor_speed/0</motorSpeedPubTopic>
          <rotorVelocitySlowdownSim>10</rotorVelocitySlowdownSim>
          <motorType>velocity</motorType>
        </plugin>
        <plugin
          filename="ignition-gazebo-multicopter-motor-model-system"
          name="gz::sim::systems::MulticopterMotorModel">
          <robotNamespace>X3</robotNamespace>
          <jointName>X3/rotor_1_joint</jointName>
          <linkName>X3/rotor_1</linkName>
          <turningDirection>ccw</turningDirection>
          <timeConstantUp>0.0125</timeConstantUp>
          <timeConstantDown>0.025</timeConstantDown>
          <maxRotVelocity>800.0</maxRotVelocity>
          <motorConstant>8.54858e-06</motorConstant>
          <momentConstant>0.016</momentConstant>
          <commandSubTopic>gazebo/command/motor_speed</commandSubTopic>
          <motorNumber>0</motorNumber>
          <rotorDragCoefficient>8.06428e-05</rotorDragCoefficient>
          <rollingMomentCoefficient>1e-06</rollingMomentCoefficient>
          <motorSpeedPubTopic>motor_speed/1</motorSpeedPubTopic>
          <rotorVelocitySlowdownSim>10</rotorVelocitySlowdownSim>
          <motorType>velocity</motorType>
        </plugin>
        <plugin
          filename="ignition-gazebo-multicopter-motor-model-system"
          name="gz::sim::systems::MulticopterMotorModel">
          <robotNamespace>X3</robotNamespace>
          <jointName>X3/rotor_2_joint</jointName>
          <linkName>X3/rotor_2</linkName>
          <turningDirection>cw</turningDirection>
          <timeConstantUp>0.0125</timeConstantUp>
          <timeConstantDown>0.025</timeConstantDown>
          <maxRotVelocity>800.0</maxRotVelocity>
          <motorConstant>8.54858e-06</motorConstant>
          <momentConstant>0.016</momentConstant>
          <commandSubTopic>gazebo/command/motor_speed</commandSubTopic>
          <motorNumber>3</motorNumber>
          <rotorDragCoefficient>8.06428e-05</rotorDragCoefficient>
          <rollingMomentCoefficient>1e-06</rollingMomentCoefficient>
          <motorSpeedPubTopic>motor_speed/2</motorSpeedPubTopic>
          <rotorVelocitySlowdownSim>10</rotorVelocitySlowdownSim>
          <motorType>velocity</motorType>
        </plugin>
        <plugin
          filename="ignition-gazebo-multicopter-motor-model-system"
          name="gz::sim::systems::MulticopterMotorModel">
          <robotNamespace>X3</robotNamespace>
          <jointName>X3/rotor_3_joint</jointName>
          <linkName>X3/rotor_3</linkName>
          <turningDirection>cw</turningDirection>
          <timeConstantUp>0.0125</timeConstantUp>
          <timeConstantDown>0.025</timeConstantDown>
          <maxRotVelocity>800.0</maxRotVelocity>
          <motorConstant>8.54858e-06</motorConstant>
          <momentConstant>0.016</momentConstant>
          <commandSubTopic>gazebo/command/motor_speed</commandSubTopic>
          <motorNumber>1</motorNumber>
          <rotorDragCoefficient>8.06428e-05</rotorDragCoefficient>
          <rollingMomentCoefficient>1e-06</rollingMomentCoefficient>
          <motorSpeedPubTopic>motor_speed/3</motorSpeedPubTopic>
          <rotorVelocitySlowdownSim>10</rotorVelocitySlowdownSim>
          <motorType>velocity</motorType>
        </plugin>

        <!-- Add anchor points for PID tuning here -->

        <!-- Ball joint allows rotation about all 3 axes -->
        <!-- <joint name="quad_ball_joint" type="ball">
        <parent>world</parent>
        <child>X3/base_link</child>
            <axis>
                <dynamics>
                <damping>0.0</damping>
                <friction>0.0</friction>
                </dynamics>
            </axis>
        </joint> -->


        <!-- Roll joint to fix around an axis -->
        <joint name="roll_joint" type="revolute">
            <parent>world</parent>
            <child>X3/base_link</child>

            <axis>
                <xyz>0 1 0</xyz> <!-- X-axis (roll) -->

                <limit>
                    <!-- Can rotate 180 degrees either way -->
                    <lower>-3.14159</lower>
                    <upper>3.14159</upper>
                    <!-- Clamp max torque -->
                    <effort>1000</effort>
                    <!-- Clamp the velocity of turns -->
                    <velocity>100</velocity> 
                </limit>

                <dynamics>
                    <damping>0.0</damping>
                    <friction>0.0</friction>
                </dynamics>
            </axis>
        </joint>




    </model>
</sdf>
